<?xml version="1.0" encoding="UTF-8"?>
<!-- Generated by org.testng.reporters.JUnitReportReporter -->
<testsuite hostname="DESKTOP-3GH4U15" failures="0" tests="1" name="APITEST.test" time="2.421" errors="1" timestamp="10 Jun 2024 14:10:19 GMT">
  <testcase classname="APITEST.test" name="ConfigurationAPI" time="2.421">
    <error message="expected:&lt;These credentials do not match our records.&gt; but was:&lt;null&gt;" type="java.lang.AssertionError">
      <![CDATA[java.lang.AssertionError: expected:<These credentials do not match our records.> but was:<null>
	at org.testng.Assert.fail(Assert.java:89)
	at org.testng.Assert.failNotEquals(Assert.java:489)
	at org.testng.Assert.assertEquals(Assert.java:118)
	at org.testng.Assert.assertEquals(Assert.java:171)
	at org.testng.Assert.assertEquals(Assert.java:181)
	at APITEST.test.ConfigurationAPI(test.java:42)
	at java.base/jdk.internal.reflect.NativeMethodAccessorImpl.invoke0(Native Method)
	at java.base/jdk.internal.reflect.NativeMethodAccessorImpl.invoke(NativeMethodAccessorImpl.java:77)
	at java.base/jdk.internal.reflect.DelegatingMethodAccessorImpl.invoke(DelegatingMethodAccessorImpl.java:43)
	at java.base/java.lang.reflect.Method.invoke(Method.java:568)
	at org.testng.internal.MethodInvocationHelper.invokeMethod(MethodInvocationHelper.java:80)
	at org.testng.internal.Invoker.invokeMethod(Invoker.java:673)
	at org.testng.internal.Invoker.invokeTestMethod(Invoker.java:842)
	at org.testng.internal.Invoker.invokeTestMethods(Invoker.java:1166)
	at org.testng.internal.TestMethodWorker.invokeTestMethods(TestMethodWorker.java:125)
	at org.testng.internal.TestMethodWorker.run(TestMethodWorker.java:109)
	at org.testng.TestRunner.runWorkers(TestRunner.java:1172)
	at org.testng.TestRunner.privateRun(TestRunner.java:757)
	at org.testng.TestRunner.run(TestRunner.java:608)
	at org.testng.SuiteRunner.runTest(SuiteRunner.java:334)
	at org.testng.SuiteRunner.runSequentially(SuiteRunner.java:329)
	at org.testng.SuiteRunner.privateRun(SuiteRunner.java:291)
	at org.testng.SuiteRunner.run(SuiteRunner.java:240)
	at org.testng.SuiteRunnerWorker.runSuite(SuiteRunnerWorker.java:52)
	at org.testng.SuiteRunnerWorker.run(SuiteRunnerWorker.java:86)
	at org.testng.TestNG.runSuitesSequentially(TestNG.java:1158)
	at org.testng.TestNG.runSuitesLocally(TestNG.java:1083)
	at org.testng.TestNG.run(TestNG.java:999)
	at org.testng.remote.AbstractRemoteTestNG.run(AbstractRemoteTestNG.java:115)
	at org.testng.remote.RemoteTestNG.initAndRun(RemoteTestNG.java:251)
	at org.testng.remote.RemoteTestNG.main(RemoteTestNG.java:77)
]]>
    </error>
  </testcase>
</testsuite>
